Workbook

Sheet ICI, GNewc, Delta
A2: Date | B2: ICI 1 | C2: ICI 2 | D2: ICI 3 | E2: ICI 4 | F2: ICI 5 | G2: NEWCASTLE | H2: CHANGE EVERY WEEK | N2: AVERAGE MONTHLY | S2: AVERAGE 2 WEEKS | X2: AVERAGE 4 WEEKS | AC2: CALCULATION | AG2: SOURCE PRICING
B3: 6500 | C3: 5800 | D3: 5000 | E3: 4200 | F3: 3400 | AG3: BME | AH3: BME | AI3: PTBA | AJ3: PTBA | AK3: ANZAWARA | AL3: ANZAWARA | AM3: MME | AN3: TRIOP FOBMV | AO3: AJE FOBMV | AP3: TRIOP | AQ3: PTBA | AR3: BAU
B4: 6200 | C4: 5500 | D4: 4600 | E4: 3800 | F4: 3000 | G4: 6322 | H4: ICI 1 | I4: ICI 2 | J4: ICI 3 | K4: ICI 4 | L4: ICI 5 | M4: NEWC | N4: ICI 1 | O4: ICI 2 | P4: ICI 3 | Q4: ICI 4 | R4: ICI 5 | S4: ICI 1 | T4: ICI 2 | U4: ICI 3 | V4: ICI 4 | W4: ICI 5 | X4: ICI 1 | Y4: ICI 2 | Z4: ICI 3 | AA4: ICI 4 | AB4: ICI 5 | AC4: ICI 1+2 | AD4: ICI 2+3 | AE4: ICI 3+4 | AF4: ICI 4+5 | AG4: SERELO | AH4: KUNGKILAN | AI4: 5000 GAR | AJ4: 48 MIND ID | AK4: EXP FOB B | AL4: DMO | AM4: S. SUM | AN4: 4200 GAR | AO4: 4100 GAR | AP4: 4200 GAR | AQ4: 50 MIND ID
A5: 40914 | B5: 114.24 | C5: 94.32 | D5: 75.2 | E5: 47.13 | F5: 36.15 | G5: 114.3 | S5: =(0+B5)/2 -> 57.12 | T5: =(0+C5)/2 -> 47.16 | U5: =(0+D5)/2 -> 37.6 | V5: =(0+E5)/2 -> 23.565 | W5: =(0+F5)/2 -> 18.075 | X5: =(0+0+0+0)/4 -> 0 | Y5: =(0+0+0+0)/4 -> 0 | Z5: =(0+0+0+0)/4 -> 0 | AA5: =(0+0+0+0)/4 -> 0 | AB5: =(0+0+0+0)/4 -> 0 | AC5: =(B5+C5)/2 -> 104.28 | AD5: =(C5+D5)/2 -> 84.76 | AE5: =(D5+E5)/2 -> 61.165 | AF5: =(E5+F5)/2 -> 41.64
A6: =A5+7 -> 40921 | B6: 115.39 | C6: 94.29 | D6: 74.89 | E6: 46.77 | F6: 36.19 | G6: 116.19 | H6: =B6-B5 -> 1.15 | I6: =C6-C5 -> -0.03 | J6: =D6-D5 -> -0.31 | K6: =E6-E5 -> -0.36 | L6: =F6-F5 -> 0.04 | S6: =(B5+B6)/2 -> 114.815 | T6: =(C5+C6)/2 -> 94.305 | U6: =(D6+D5)/2 -> 75.045 | V6: =(E5+E6)/2 -> 46.95 | W6: =(F5+F6)/2 -> 36.17 | X6: =(0+0+0+0)/4 -> 0 | Y6: =(0+0+0+0)/4 -> 0 | Z6: =(0+0+0+0)/4 -> 0 | AA6: =(0+0+0+0)/4 -> 0 | AB6: =(0+0+0+0)/4 -> 0 | AC6: =(B6+C6)/2 -> 104.84 | AD6: =(C6+D6)/2 -> 84.59 | AE6: =(D6+E6)/2 -> 60.83 | AF6: =(E6+F6)/2 -> 41.48
A7: =A6+7 -> 40928 | B7: 115.38 | C7: 94.07 | D7: 74.27 | E7: 46.72 | F7: 36.29 | G7: 116.53 | H7: =B7-B6 -> -0.01 | I7: =C7-C6 -> -0.22 | J7: =D7-D6 -> -0.62 | K7: =E7-E6 -> -0.05 | L7: =F7-F6 -> 0.1 | S7: =(B6+B7)/2 -> 115.385 | T7: =(C6+C7)/2 -> 94.18 | U7: =(D7+D6)/2 -> 74.58 | V7: =(E6+E7)/2 -> 46.745 | W7: =(F6+F7)/2 -> 36.24 | X7: =(0+0+0+0)/4 -> 0 | Y7: =(0+0+0+0)/4 -> 0 | Z7: =(0+0+0+0)/4 -> 0 | AA7: =(0+0+0+0)/4 -> 0 | AB7: =(0+0+0+0)/4 -> 0 | AC7: =(B7+C7)/2 -> 104.725 | AD7: =(C7+D7)/2 -> 84.17 | AE7: =(D7+E7)/2 -> 60.495 | AF7: =(E7+F7)/2 -> 41.505
A8: =A7+7 -> 40935 | B8: 117.54 | C8: 94.64 | D8: 75.14 | E8: 46.68 | F8: 36.19 | G8: 122.16 | H8: =B8-B7 -> 2.16 | I8: =C8-C7 -> 0.57 | J8: =D8-D7 -> 0.87 | K8: =E8-E7 -> -0.04 | L8: =F8-F7 -> -0.1 | S8: =(B7+B8)/2 -> 116.46 | T8: =(C7+C8)/2 -> 94.355 | U8: =(D8+D7)/2 -> 74.705 | V8: =(E7+E8)/2 -> 46.7 | W8: =(F7+F8)/2 -> 36.24 | X8: =(SUM(B5:B8))/4 -> 115.6375 | Y8: =(SUM(C5:C8))/4 -> 94.33 | Z8: =(SUM(D5:D8))/4 -> 74.875 | AA8: =(SUM(E5:E8))/4 -> 46.825 | AB8: =(SUM(F5:F8))/4 -> 36.205 | AC8: =(B8+C8)/2 -> 106.09 | AD8: =(C8+D8)/2 -> 84.89 | AE8: =(D8+E8)/2 -> 60.91 | AF8: =(E8+F8)/2 -> 41.435
A9: =A8+7 -> 40942 | B9: 117.46 | C9: 94.72 | D9: 75.27 | E9: 46.63 | F9: 36.27 | G9: 118.78 | H9: =B9-B8 -> -0.08 | I9: =C9-C8 -> 0.08 | J9: =D9-D8 -> 0.13 | K9: =E9-E8 -> -0.05 | L9: =F9-F8 -> 0.08 | S9: =(B8+B9)/2 -> 117.5 | T9: =(C8+C9)/2 -> 94.68 | U9: =(D9+D8)/2 -> 75.205 | V9: =(E8+E9)/2 -> 46.655 | W9: =(F8+F9)/2 -> 36.23 | X9: =(SUM(B6:B9))/4 -> 116.4425 | Y9: =(SUM(C6:C9))/4 -> 94.43 | Z9: =(SUM(D6:D9))/4 -> 74.8925 | AA9: =(SUM(E6:E9))/4 -> 46.7 | AB9: =(SUM(F6:F9))/4 -> 36.235 | AC9: =(B9+C9)/2 -> 106.09 | AD9: =(C9+D9)/2 -> 84.995 | AE9: =(D9+E9)/2 -> 60.95 | AF9: =(E9+F9)/2 -> 41.45
A10: =A9+7 -> 40949 | B10: 116.31 | C10: 95.72 | D10: 75.63 | E10: 47.2 | F10: 36.78 | G10: 117.32 | H10: =B10-B9 -> -1.15 | I10: =C10-C9 -> 1 | J10: =D10-D9 -> 0.36 | K10: =E10-E9 -> 0.57 | L10: =F10-F9 -> 0.51 | S10: =(B9+B10)/2 -> 116.885 | T10: =(C9+C10)/2 -> 95.22 | U10: =(D10+D9)/2 -> 75.45 | V10: =(E9+E10)/2 -> 46.915 | W10: =(F9+F10)/2 -> 36.525 | X10: =(SUM(B7:B10))/4 -> 116.6725 | Y10: =(SUM(C7:C10))/4 -> 94.7875 | Z10: =(SUM(D7:D10))/4 -> 75.0775 | AA10: =(SUM(E7:E10))/4 -> 46.8075 | AB10: =(SUM(F7:F10))/4 -> 36.3825 | AC10: =(B10+C10)/2 -> 106.015 | AD10: =(C10+D10)/2 -> 85.675 | AE10: =(D10+E10)/2 -> 61.415 | AF10: =(E10+F10)/2 -> 41.99
A11: =A10+7 -> 40956 | B11: 116.36 | C11: 94.51 | D11: 74.23 | E11: 46.84 | F11: 35.78 | G11: 118.89 | H11: =B11-B10 -> 0.05 | I11: =C11-C10 -> -1.21 | J11: =D11-D10 -> -1.4 | K11: =E11-E10 -> -0.36 | L11: =F11-F10 -> -1 | S11: =(B10+B11)/2 -> 116.335 | T11: =(C10+C11)/2 -> 95.115 | U11: =(D11+D10)/2 -> 74.93 | V11: =(E10+E11)/2 -> 47.02 | W11: =(F10+F11)/2 -> 36.28 | X11: =(SUM(B8:B11))/4 -> 116.9175 | Y11: =(SUM(C8:C11))/4 -> 94.8975 | Z11: =(SUM(D8:D11))/4 -> 75.0675 | AA11: =(SUM(E8:E11))/4 -> 46.8375 | AB11: =(SUM(F8:F11))/4 -> 36.255 | AC11: =(B11+C11)/2 -> 105.435 | AD11: =(C11+D11)/2 -> 84.37 | AE11: =(D11+E11)/2 -> 60.535 | AF11: =(E11+F11)/2 -> 41.31
A12: =A11+7 -> 40963 | B12: 116.07 | C12: 93.67 | D12: 73.29 | E12: 46.59 | F12: 35.79 | G12: 116.55 | H12: =B12-B11 -> -0.29 | I12: =C12-C11 -> -0.84 | J12: =D12-D11 -> -0.94 | K12: =E12-E11 -> -0.25 | L12: =F12-F11 -> 0.01 | S12: =(B11+B12)/2 -> 116.215 | T12: =(C11+C12)/2 -> 94.09 | U12: =(D12+D11)/2 -> 73.76 | V12: =(E11+E12)/2 -> 46.715 | W12: =(F11+F12)/2 -> 35.785 | X12: =(SUM(B9:B12))/4 -> 116.55 | Y12: =(SUM(C9:C12))/4 -> 94.655 | Z12: =(SUM(D9:D12))/4 -> 74.605 | AA12: =(SUM(E9:E12))/4 -> 46.815 | AB12: =(SUM(F9:F12))/4 -> 36.155 | AC12: =(B12+C12)/2 -> 104.87 | AD12: =(C12+D12)/2 -> 83.48 | AE12: =(D12+E12)/2 -> 59.94 | AF12: =(E12+F12)/2 -> 41.19
A13: =A12+7 -> 40970 | B13: 114.23 | C13: 92.76 | D13: 73.01 | E13: 46.11 | F13: 35.54 | G13: 111.07 | H13: =B13-B12 -> -1.84 | I13: =C13-C12 -> -0.91 | J13: =D13-D12 -> -0.28 | K13: =E13-E12 -> -0.48 | L13: =F13-F12 -> -0.25 | S13: =(B12+B13)/2 -> 115.15 | T13: =(C12+C13)/2 -> 93.215 | U13: =(D13+D12)/2 -> 73.15 | V13: =(E12+E13)/2 -> 46.35 | W13: =(F12+F13)/2 -> 35.665 | X13: =(SUM(B10:B13))/4 -> 115.7425 | Y13: =(SUM(C10:C13))/4 -> 94.165 | Z13: =(SUM(D10:D13))/4 -> 74.04 | AA13: =(SUM(E10:E13))/4 -> 46.685 | AB13: =(SUM(F10:F13))/4 -> 35.9725 | AC13: =(B13+C13)/2 -> 103.495 | AD13: =(C13+D13)/2 -> 82.885 | AE13: =(D13+E13)/2 -> 59.56 | AF13: =(E13+F13)/2 -> 40.825
A14: =A13+7 -> 40977 | B14: 111.65 | C14: 91.6 | D14: 72.21 | E14: 45.46 | F14: 35.17 | G14: 111.65 | H14: =B14-B13 -> -2.58 | I14: =C14-C13 -> -1.16 | J14: =D14-D13 -> -0.8 | K14: =E14-E13 -> -0.65 | L14: =F14-F13 -> -0.37 | S14: =(B13+B14)/2 -> 112.94 | T14: =(C13+C14)/2 -> 92.18 | U14: =(D14+D13)/2 -> 72.61 | V14: =(E13+E14)/2 -> 45.785 | W14: =(F13+F14)/2 -> 35.355 | X14: =(SUM(B11:B14))/4 -> 114.5775 | Y14: =(SUM(C11:C14))/4 -> 93.135 | Z14: =(SUM(D11:D14))/4 -> 73.185 | AA14: =(SUM(E11:E14))/4 -> 46.25 | AB14: =(SUM(F11:F14))/4 -> 35.57 | AC14: =(B14+C14)/2 -> 101.625 | AD14: =(C14+D14)/2 -> 81.905 | AE14: =(D14+E14)/2 -> 58.835 | AF14: =(E14+F14)/2 -> 40.315
A15: =A14+7 -> 40984 | B15: 109.76 | C15: 91.19 | D15: 71.6 | E15: 44.13 | F15: 34.99 | G15: 105.24 | H15: =B15-B14 -> -1.89 | I15: =C15-C14 -> -0.41 | J15: =D15-D14 -> -0.61 | K15: =E15-E14 -> -1.33 | L15: =F15-F14 -> -0.18 | S15: =(B14+B15)/2 -> 110.705 | T15: =(C14+C15)/2 -> 91.395 | U15: =(D15+D14)/2 -> 71.905 | V15: =(E14+E15)/2 -> 44.795 | W15: =(F14+F15)/2 -> 35.08 | X15: =(SUM(B12:B15))/4 -> 112.9275 | Y15: =(SUM(C12:C15))/4 -> 92.305 | Z15: =(SUM(D12:D15))/4 -> 72.5275 | AA15: =(SUM(E12:E15))/4 -> 45.5725 | AB15: =(SUM(F12:F15))/4 -> 35.3725 | AC15: =(B15+C15)/2 -> 100.475 | AD15: =(C15+D15)/2 -> 81.395 | AE15: =(D15+E15)/2 -> 57.865 | AF15: =(E15+F15)/2 -> 39.56
A16: =A15+7 -> 40991 | B16: 109.78 | C16: 90.5 | D16: 71.59 | E16: 44.6 | F16: 34.73 | G16: 105.2 | H16: =B16-B15 -> 0.02 | I16: =C16-C15 -> -0.69 | J16: =D16-D15 -> -0.01 | K16: =E16-E15 -> 0.47 | L16: =F16-F15 -> -0.26 | S16: =(B15+B16)/2 -> 109.77 | T16: =(C15+C16)/2 -> 90.845 | U16: =(D16+D15)/2 -> 71.595 | V16: =(E15+E16)/2 -> 44.365 | W16: =(F15+F16)/2 -> 34.86 | X16: =(SUM(B13:B16))/4 -> 111.355 | Y16: =(SUM(C13:C16))/4 -> 91.5125 | Z16: =(SUM(D13:D16))/4 -> 72.1025 | AA16: =(SUM(E13:E16))/4 -> 45.075 | AB16: =(SUM(F13:F16))/4 -> 35.1075 | AC16: =(B16+C16)/2 -> 100.14 | AD16: =(C16+D16)/2 -> 81.045 | AE16: =(D16+E16)/2 -> 58.095 | AF16: =(E16+F16)/2 -> 39.665
A17: =A16+7 -> 40998 | B17: 109.63 | C17: 90.82 | D17: 71.7 | E17: 44.9 | F17: 34.71 | G17: 107.04 | H17: =B17-B16 -> -0.15 | I17: =C17-C16 -> 0.32 | J17: =D17-D16 -> 0.11 | K17: =E17-E16 -> 0.3 | L17: =F17-F16 -> -0.02 | S17: =(B16+B17)/2 -> 109.705 | T17: =(C16+C17)/2 -> 90.66 | U17: =(D17+D16)/2 -> 71.645 | V17: =(E16+E17)/2 -> 44.75 | W17: =(F16+F17)/2 -> 34.72 | X17: =(SUM(B14:B17))/4 -> 110.205 | Y17: =(SUM(C14:C17))/4 -> 91.0275 | Z17: =(SUM(D14:D17))/4 -> 71.775 | AA17: =(SUM(E14:E17))/4 -> 44.7725 | AB17: =(SUM(F14:F17))/4 -> 34.9 | AC17: =(B17+C17)/2 -> 100.225 | AD17: =(C17+D17)/2 -> 81.26 | AE17: =(D17+E17)/2 -> 58.3 | AF17: =(E17+F17)/2 -> 39.805
A18: =A17+7 -> 41005 | B18: 110.43 | C18: 91.22 | D18: 71.81 | E18: 48.87 | F18: 34.81 | G18: 107.01 | H18: =B18-B17 -> 0.8 | I18: =C18-C17 -> 0.4 | J18: =D18-D17 -> 0.11 | K18: =E18-E17 -> 3.97 | L18: =F18-F17 -> 0.1 | S18: =(B17+B18)/2 -> 110.03 | T18: =(C17+C18)/2 -> 91.02 | U18: =(D18+D17)/2 -> 71.755 | V18: =(E17+E18)/2 -> 46.885 | W18: =(F17+F18)/2 -> 34.76 | X18: =(SUM(B15:B18))/4 -> 109.9 | Y18: =(SUM(C15:C18))/4 -> 90.9325 | Z18: =(SUM(D15:D18))/4 -> 71.675 | AA18: =(SUM(E15:E18))/4 -> 45.625 | AB18: =(SUM(F15:F18))/4 -> 34.81 | AC18: =(B18+C18)/2 -> 100.825 | AD18: =(C18+D18)/2 -> 81.515 | AE18: =(D18+E18)/2 -> 60.34 | AF18: =(E18+F18)/2 -> 41.84
A19: =A18+7 -> 41012 | B19: 107.21 | C19: 91.45 | D19: 72.39 | E19: 49.15 | F19: 35.28 | G19: 102.91 | H19: =B19-B18 -> -3.22 | I19: =C19-C18 -> 0.23 | J19: =D19-D18 -> 0.58 | K19: =E19-E18 -> 0.28 | L19: =F19-F18 -> 0.47 | S19: =(B18+B19)/2 -> 108.82 | T19: =(C18+C19)/2 -> 91.335 | U19: =(D19+D18)/2 -> 72.1 | V19: =(E18+E19)/2 -> 49.01 | W19: =(F18+F19)/2 -> 35.045 | X19: =(SUM(B16:B19))/4 -> 109.2625 | Y19: =(SUM(C16:C19))/4 -> 90.9975 | Z19: =(SUM(D16:D19))/4 -> 71.8725 | AA19: =(SUM(E16:E19))/4 -> 46.88 | AB19: =(SUM(F16:F19))/4 -> 34.8825 | AC19: =(B19+C19)/2 -> 99.33 | AD19: =(C19+D19)/2 -> 81.92 | AE19: =(D19+E19)/2 -> 60.77 | AF19: =(E19+F19)/2 -> 42.215
... A22: =A21+7 -> 41033 | B22: 101.4 | C22: 89.24 | D22: 72.1 | E22: 49.98 | F22: 35.21 | G22: 99.24 | H22: =B22-B21 -> -1.57 | I22: =C22-C21 -> -1.67 | J22: =D22-D21 -> -0.04 | K22: =E22-E21 -> -0.51 | L22: =F22-F21 -> -0.18 | S22: =(B21+B22)/2 -> 102.185 | T22: =(C21+C22)/2 -> 90.075 | U22: =(D22+D21)/2 -> 72.12 | V22: =(E21+E22)/2 -> 50.235 | W22: =(F21+F22)/2 -> 35.3 | X22: =(SUM(B19:B22))/4 -> 104.0025 | Y22: =(SUM(C19:C22))/4 -> 90.7 | Z22: =(SUM(D19:D22))/4 -> 72.2675 | AA22: =(SUM(E19:E22))/4 -> 49.96 | AB22: =(SUM(F19:F22))/4 -> 35.36 | AC22: =(B22+C22)/2 -> 95.32 | AD22: =(C22+D22)/2 -> 80.67 | AE22: =(D22+E22)/2 -> 61.04 | AF22: =(E22+F22)/2 -> 42.595
A23: =A22+7 -> 41040 | B23: 101.35 | C23: 87.82 | E23: 49 | F23: 35.06 | G23: 103.37 | H23: =B23-B22 -> -0.05 | I23: =C23-C22 -> -1.42 | J23: =D23-D22 -> #VALUE! | K23: =E23-E22 -> -0.98 | L23: =F23-F22 -> -0.15 | S23: =(B22+B23)/2 -> 101.375 | T23: =(C22+C23)/2 -> 88.53 | U23: =(D23+D22)/2 -> #VALUE! | V23: =(E22+E23)/2 -> 49.49 | W23: =(F22+F23)/2 -> 35.135 | X23: =(SUM(B20:B23))/4 -> 102.5375 | Y23: =(SUM(C20:C23))/4 -> 89.7925 | Z23: =(SUM(D20:D23))/4 -> 54.17 | AA23: =(SUM(E20:E23))/4 -> 49.9225 | AB23: =(SUM(F20:F23))/4 -> 35.305 | AC23: =(B23+C23)/2 -> 94.585 | AD23: =(C23+D23)/2 -> #VALUE! | AE23: =(D23+E23)/2 -> #VALUE! | AF23: =(E23+F23)/2 -> 42.03
A24: =A23+7 -> 41047 | B24: 99.1 | C24: 87.56 | D24: 70.63 | E24: 49.23 | F24: 34.84 | G24: 97.45 | H24: =B24-B23 -> -2.25 | I24: =C24-C23 -> -0.26 | J24: =D24-D23 -> #VALUE! | K24: =E24-E23 -> 0.23 | L24: =F24-F23 -> -0.22 | S24: =(B23+B24)/2 -> 100.225 | T24: =(C23+C24)/2 -> 87.69 | U24: =(D24+D23)/2 -> #VALUE! | V24: =(E23+E24)/2 -> 49.115 | W24: =(F23+F24)/2 -> 34.95 | X24: =(SUM(B21:B24))/4 -> 101.205 | Y24: =(SUM(C21:C24))/4 -> 88.8825 | Z24: =(SUM(D21:D24))/4 -> 53.7175 | AA24: =(SUM(E21:E24))/4 -> 49.675 | AB24: =(SUM(F21:F24))/4 -> 35.125 | AC24: =(B24+C24)/2 -> 93.33 | AD24: =(C24+D24)/2 -> 79.095 | AE24: =(D24+E24)/2 -> 59.93 | AF24: =(E24+F24)/2 -> 42.035
A25: =A24+7 -> 41054 | B25: 94.82 | C25: 85.04 | D25: 68.21 | E25: 48.4 | F25: 34.64 | G25: 92.88 | H25: =B25-B24 -> -4.28 | I25: =C25-C24 -> -2.52 | J25: =D25-D24 -> -2.42 | K25: =E25-E24 -> -0.83 | L25: =F25-F24 -> -0.2 | S25: =(B24+B25)/2 -> 96.96 | T25: =(C24+C25)/2 -> 86.3 | U25: =(D25+D24)/2 -> 69.42 | V25: =(E24+E25)/2 -> 48.815 | W25: =(F24+F25)/2 -> 34.74 | X25: =(SUM(B22:B25))/4 -> 99.1675 | Y25: =(SUM(C22:C25))/4 -> 87.415 | Z25: =(SUM(D22:D25))/4 -> 52.735 | AA25: =(SUM(E22:E25))/4 -> 49.1525 | AB25: =(SUM(F22:F25))/4 -> 34.9375 | AC25: =(B25+C25)/2 -> 89.93 | AD25: =(C25+D25)/2 -> 76.625 | AE25: =(D25+E25)/2 -> 58.305 | AF25: =(E25+F25)/2 -> 41.52
A26: =A25+7 -> 41061 | B26: 92.51 | C26: 83.81 | D26: 65.72 | E26: 47.46 | F26: 34.28 | G26: 92.15 | H26: =B26-B25 -> -2.31 | I26: =C26-C25 -> -1.23 | J26: =D26-D25 -> -2.49 | K26: =E26-E25 -> -0.94 | L26: =F26-F25 -> -0.36 | S26: =(B25+B26)/2 -> 93.665 | T26: =(C25+C26)/2 -> 84.425 | U26: =(D26+D25)/2 -> 66.965 | V26: =(E25+E26)/2 -> 47.93 | W26: =(F25+F26)/2 -> 34.46 | X26: =(SUM(B23:B26))/4 -> 96.945 | Y26: =(SUM(C23:C26))/4 -> 86.0575 | Z26: =(SUM(D23:D26))/4 -> 51.14 | AA26: =(SUM(E23:E26))/4 -> 48.5225 | AB26: =(SUM(F23:F26))/4 -> 34.705 | AC26: =(B26+C26)/2 -> 88.16 | AD26: =(C26+D26)/2 -> 74.765 | AE26: =(D26+E26)/2 -> 56.59 | AF26: =(E26+F26)/2 -> 40.87
A27: =A26+7 -> 41068 | B27: 91.89 | C27: 82.21 | D27: 65.04 | E27: 46.55 | F27: 33.99 | G27: 90.33 | H27: =B27-B26 -> -0.62 | I27: =C27-C26 -> -1.6 | J27: =D27-D26 -> -0.68 | K27: =E27-E26 -> -0.91 | L27: =F27-F26 -> -0.29 | S27: =(B26+B27)/2 -> 92.2 | T27: =(C26+C27)/2 -> 83.01 | U27: =(D27+D26)/2 -> 65.38 | V27: =(E26+E27)/2 -> 47.005 | W27: =(F26+F27)/2 -> 34.135 | X27: =(SUM(B24:B27))/4 -> 94.58 | Y27: =(SUM(C24:C27))/4 -> 84.655 | Z27: =(SUM(D24:D27))/4 -> 67.4 | AA27: =(SUM(E24:E27))/4 -> 47.91 | AB27: =(SUM(F24:F27))/4 -> 34.4375 | AC27: =(B27+C27)/2 -> 87.05 | AD27: =(C27+D27)/2 -> 73.625 | AE27: =(D27+E27)/2 -> 55.795 | AF27: =(E27+F27)/2 -> 40.27
A28: =A27+7 -> 41075 | B28: 89.25 | C28: 78.62 | D28: 63.66 | E28: 44.81 | F28: 33.39 | G28: 85.03 | H28: =B28-B27 -> -2.64 | I28: =C28-C27 -> -3.59 | J28: =D28-D27 -> -1.38 | K28: =E28-E27 -> -1.74 | L28: =F28-F27 -> -0.6 | S28: =(B27+B28)/2 -> 90.57 | T28: =(C27+C28)/2 -> 80.415 | U28: =(D28+D27)/2 -> 64.35 | V28: =(E27+E28)/2 -> 45.68 | W28: =(F27+F28)/2 -> 33.69 | X28: =(SUM(B25:B28))/4 -> 92.1175 | Y28: =(SUM(C25:C28))/4 -> 82.42 | Z28: =(SUM(D25:D28))/4 -> 65.6575 | AA28: =(SUM(E25:E28))/4 -> 46.805 | AB28: =(SUM(F25:F28))/4 -> 34.075 | AC28: =(B28+C28)/2 -> 83.935 | AD28: =(C28+D28)/2 -> 71.14 | AE28: =(D28+E28)/2 -> 54.235 | AF28: =(E28+F28)/2 -> 39.1
A29: =A28+7 -> 41082 | B29: 86.7 | C29: 75.92 | D29: 61.46 | E29: 42.97 | F29: 32.94 | G29: 84.98 | H29: =B29-B28 -> -2.55 | I29: =C29-C28 -> -2.7 | J29: =D29-D28 -> -2.2 | K29: =E29-E28 -> -1.84 | L29: =F29-F28 -> -0.45 | S29: =(B28+B29)/2 -> 87.975 | T29: =(C28+C29)/2 -> 77.27 | U29: =(D29+D28)/2 -> 62.56 | V29: =(E28+E29)/2 -> 43.89 | W29: =(F28+F29)/2 -> 33.165 | X29: =(SUM(B26:B29))/4 -> 90.0875 | Y29: =(SUM(C26:C29))/4 -> 80.14 | Z29: =(SUM(D26:D29))/4 -> 63.97 | AA29: =(SUM(E26:E29))/4 -> 45.4475 | AB29: =(SUM(F26:F29))/4 -> 33.65 | AC29: =(B29+C29)/2 -> 81.31 | AD29: =(C29+D29)/2 -> 68.69 | AE29: =(D29+E29)/2 -> 52.215 | AF29: =(E29+F29)/2 -> 37.955
A30: =A29+7 -> 41089 | B30: 87.7 | C30: 73.65 | D30: 60.34 | E30: 42.35 | F30: 32.74 | G30: 89.22 | H30: =B30-B29 -> 1 | I30: =C30-C29 -> -2.27 | J30: =D30-D29 -> -1.12 | K30: =E30-E29 -> -0.62 | L30: =F30-F29 -> -0.2 | S30: =(B29+B30)/2 -> 87.2 | T30: =(C29+C30)/2 -> 74.785 | U30: =(D30+D29)/2 -> 60.9 | V30: =(E29+E30)/2 -> 42.66 | W30: =(F29+F30)/2 -> 32.84 | X30: =(SUM(B27:B30))/4 -> 88.885 | Y30: =(SUM(C27:C30))/4 -> 77.6 | Z30: =(SUM(D27:D30))/4 -> 62.625 | AA30: =(SUM(E27:E30))/4 -> 44.17 | AB30: =(SUM(F27:F30))/4 -> 33.265 | AC30: =(B30+C30)/2 -> 80.675 | AD30: =(C30+D30)/2 -> 66.995 | AE30: =(D30+E30)/2 -> 51.345 | AF30: =(E30+F30)/2 -> 37.545
A31: =A30+7 -> 41096 | B31: 89.17 | C31: 73.29 | D31: 60.16 | E31: 41.3 | F31: 32.38 | G31: 90.4 | H31: =B31-B30 -> 1.47 | I31: =C31-C30 -> -0.36 | J31: =D31-D30 -> -0.18 | K31: =E31-E30 -> -1.05 | L31: =F31-F30 -> -0.36 | S31: =(B30+B31)/2 -> 88.435 | T31: =(C30+C31)/2 -> 73.47 | U31: =(D31+D30)/2 -> 60.25 | V31: =(E30+E31)/2 -> 41.825 | W31: =(F30+F31)/2 -> 32.56 | X31: =(SUM(B28:B31))/4 -> 88.205 | Y31: =(SUM(C28:C31))/4 -> 75.37 | Z31: =(SUM(D28:D31))/4 -> 61.405 | AA31: =(SUM(E28:E31))/4 -> 42.8575 | AB31: =(SUM(F28:F31))/4 -> 32.8625 | AC31: =(B31+C31)/2 -> 81.23 | AD31: =(C31+D31)/2 -> 66.725 | AE31: =(D31+E31)/2 -> 50.73 | AF31: =(E31+F31)/2 -> 36.84
A32: =A31+7 -> 41103 | B32: 86.99 | C32: 72.28 | D32: 59.59 | E32: 40.67 | F32: 31.64 | G32: 87.73 | H32: =B32-B31 -> -2.18 | I32: =C32-C31 -> -1.01 | J32: =D32-D31 -> -0.57 | K32: =E32-E31 -> -0.63 | L32: =F32-F31 -> -0.74 | S32: =(B31+B32)/2 -> 88.08 | T32: =(C31+C32)/2 -> 72.785 | U32: =(D32+D31)/2 -> 59.875 | V32: =(E31+E32)/2 -> 40.985 | W32: =(F31+F32)/2 -> 32.01 | X32: =(SUM(B29:B32))/4 -> 87.64 | Y32: =(SUM(C29:C32))/4 -> 73.785 | Z32: =(SUM(D29:D32))/4 -> 60.3875 | AA32: =(SUM(E29:E32))/4 -> 41.8225 | AB32: =(SUM(F29:F32))/4 -> 32.425 | AC32: =(B32+C32)/2 -> 79.635 | AD32: =(C32+D32)/2 -> 65.935 | AE32: =(D32+E32)/2 -> 50.13 | AF32: =(E32+F32)/2 -> 36.155
A33: =A32+7 -> 41110 | B33: 85.55 | C33: 70.84 | D33: 56.51 | E33: 39.58 | F33: 30.37 | G33: 87.99 | H33: =B33-B32 -> -1.44 | I33: =C33-C32 -> -1.44 | J33: =D33-D32 -> -3.08 | K33: =E33-E32 -> -1.09 | L33: =F33-F32 -> -1.27 | S33: =(B32+B33)/2 -> 86.27 | T33: =(C32+C33)/2 -> 71.56 | U33: =(D33+D32)/2 -> 58.05 | V33: =(E32+E33)/2 -> 40.125 | W33: =(F32+F33)/2 -> 31.005 | X33: =(SUM(B30:B33))/4 -> 87.3525 | Y33: =(SUM(C30:C33))/4 -> 72.515 | Z33: =(SUM(D30:D33))/4 -> 59.15 | AA33: =(SUM(E30:E33))/4 -> 40.975 | AB33: =(SUM(F30:F33))/4 -> 31.7825 | AC33: =(B33+C33)/2 -> 78.195 | AD33: =(C33+D33)/2 -> 63.675 | AE33: =(D33+E33)/2 -> 48.045 | AF33: =(E33+F33)/2 -> 34.975
A34: =A33+7 -> 41117 | B34: 84.09 | C34: 70.3 | D34: 57.37 | E34: 39.58 | F34: 30.06 | G34: 88.41 | H34: =B34-B33 -> -1.46 | I34: =C34-C33 -> -0.54 | J34: =D34-D33 -> 0.86 | K34: =E34-E33 -> 0 | L34: =F34-F33 -> -0.31 | S34: =(B33+B34)/2 -> 84.82 | T34: =(C33+C34)/2 -> 70.57 | U34: =(D34+D33)/2 -> 56.94 | V34: =(E33+E34)/2 -> 39.58 | W34: =(F33+F34)/2 -> 30.215 | X34: =(SUM(B31:B34))/4 -> 86.45 | Y34: =(SUM(C31:C34))/4 -> 71.6775 | Z34: =(SUM(D31:D34))/4 -> 58.4075 | AA34: =(SUM(E31:E34))/4 -> 40.2825 | AB34: =(SUM(F31:F34))/4 -> 31.1125 | AC34: =(B34+C34)/2 -> 77.195 | AD34: =(C34+D34)/2 -> 63.835 | AE34: =(D34+E34)/2 -> 48.475 | AF34: =(E34+F34)/2 -> 34.82
A35: =A34+7 -> 41124 | B35: 86.31 | C35: 70.34 | D35: 56.73 | E35: 40.22 | F35: 29.79 | G35: 89.95 | H35: =B35-B34 -> 2.22 | I35: =C35-C34 -> 0.04 | J35: =D35-D34 -> -0.64 | K35: =E35-E34 -> 0.64 | L35: =F35-F34 -> -0.27 | S35: =(B34+B35)/2 -> 85.2 | T35: =(C34+C35)/2 -> 70.32 | U35: =(D35+D34)/2 -> 57.05 | V35: =(E34+E35)/2 -> 39.9 | W35: =(F34+F35)/2 -> 29.925 | X35: =(SUM(B32:B35))/4 -> 85.735 | Y35: =(SUM(C32:C35))/4 -> 70.94 | Z35: =(SUM(D32:D35))/4 -> 57.55 | AA35: =(SUM(E32:E35))/4 -> 40.0125 | AB35: =(SUM(F32:F35))/4 -> 30.465 | AC35: =(B35+C35)/2 -> 78.325 | AD35: =(C35+D35)/2 -> 63.535 | AE35: =(D35+E35)/2 -> 48.475 | AF35: =(E35+F35)/2 -> 35.005
... A421: =A420+7 -> 43826 | B421: 68.89 | C421: 59.17 | D421: 49.17 | E421: 33.83 | F421: 21.43 | G421: 66.19 | H421: =B421-B420 -> -0.16 | I421: =C421-C420 -> -0.05 | J421: =D421-D420 -> -0.26 | K421: =E421-E420 -> -0.33 | L421: =F421-F420 -> -0.05 | S421: =(B420+B421)/2 -> 68.97 | T421: =(C420+C421)/2 -> 59.195 | U421: =(D421+D420)/2 -> 49.3 | V421: =(E420+E421)/2 -> 33.995 | W421: =(F420+F421)/2 -> 21.455 | X421: =(SUM(B418:B421))/4 -> 69.1325 | Y421: =(SUM(C418:C421))/4 -> 59.28 | Z421: =(SUM(D418:D421))/4 -> 49.465 | AA421: =(SUM(E418:E421))/4 -> 34.235 | AB421: =(SUM(F418:F421))/4 -> 21.5475 | AC421: =(B421+C421)/2 -> 64.03 | AD421: =(C421+D421)/2 -> 54.17 | AE421: =(D421+E421)/2 -> 41.5 | AF421: =(E421+F421)/2 -> 27.63
A422: =A421+7 -> 43833 | B422: 68.42 | C422: 58.8 | D422: 49.01 | E422: 33.77 | F422: 21.25 | G422: 64.8 | H422: =B422-B421 -> -0.47 | I422: =C422-C421 -> -0.37 | J422: =D422-D421 -> -0.16 | K422: =E422-E421 -> -0.06 | L422: =F422-F421 -> -0.18 | M422: =G422-G421 -> -1.39 | N422: =AVERAGE(B422:B426) -> 69.036 | O422: =AVERAGE(C422:C426) -> 59.692 | P422: =AVERAGE(D422:D426) -> 49.678 | Q422: =AVERAGE(E422:E426) -> 34.808 | R422: =AVERAGE(F422:F426) -> 21.608 | S422: =(B421+B422)/2 -> 68.655 | T422: =(C421+C422)/2 -> 58.985 | U422: =(D422+D421)/2 -> 49.09 | V422: =(E421+E422)/2 -> 33.8 | W422: =(F421+F422)/2 -> 21.34 | X422: =(SUM(B419:B422))/4 -> 68.91 | Y422: =(SUM(C419:C422))/4 -> 59.1275 | Z422: =(SUM(D419:D422))/4 -> 49.295 | AA422: =(SUM(E419:E422))/4 -> 34.07 | AB422: =(SUM(F419:F422))/4 -> 21.4425 | AC422: =(B422+C422)/2 -> 63.61 | AD422: =(C422+D422)/2 -> 53.905 | AE422: =(D422+E422)/2 -> 41.39 | AF422: =(E422+F422)/2 -> 27.51 | AK422: =((V422+W422)/2)-5.35 -> 22.22
A423: =A422+7 -> 43840 | B423: 68.78 | C423: 59.48 | D423: 49.39 | E423: 34.27 | F423: 21.27 | G423: 68.67 | H423: =B423-B422 -> 0.36 | I423: =C423-C422 -> 0.68 | J423: =D423-D422 -> 0.38 | K423: =E423-E422 -> 0.5 | L423: =F423-F422 -> 0.02 | M423: =G423-G422 -> 3.87 | N423: =N422 -> 69.036 | O423: =O422 -> 59.692 | P423: =P422 -> 49.678 | Q423: =Q422 -> 34.808 | R423: =R422 -> 21.608 | S423: =(B422+B423)/2 -> 68.6 | T423: =(C422+C423)/2 -> 59.14 | U423: =(D423+D422)/2 -> 49.2 | V423: =(E422+E423)/2 -> 34.02 | W423: =(F422+F423)/2 -> 21.26 | X423: =(SUM(B420:B423))/4 -> 68.785 | Y423: =(SUM(C420:C423))/4 -> 59.1675 | Z423: =(SUM(D420:D423))/4 -> 49.25 | AA423: =(SUM(E420:E423))/4 -> 34.0075 | AB423: =(SUM(F420:F423))/4 -> 21.3575 | AC423: =(B423+C423)/2 -> 64.13 | AD423: =(C423+D423)/2 -> 54.435 | AE423: =(D423+E423)/2 -> 41.83 | AF423: =(E423+F423)/2 -> 27.77 | AK423: =((V423+W423)/2)-5.35 -> 22.29
A424: =A423+7 -> 43847 | B424: 69.25 | C424: 59.94 | D424: 49.58 | E424: 35.08 | F424: 21.77 | G424: 73.78 | H424: =B424-B423 -> 0.47 | I424: =C424-C423 -> 0.46 | J424: =D424-D423 -> 0.19 | K424: =E424-E423 -> 0.81 | L424: =F424-F423 -> 0.5 | M424: =G424-G423 -> 5.11 | N424: =N423 -> 69.036 | O424: =O423 -> 59.692 | P424: =P423 -> 49.678 | Q424: =Q423 -> 34.808 | R424: =R423 -> 21.608 | S424: =(B423+B424)/2 -> 69.015 | T424: =(C423+C424)/2 -> 59.71 | U424: =(D424+D423)/2 -> 49.485 | V424: =(E423+E424)/2 -> 34.675 | W424: =(F423+F424)/2 -> 21.52 | X424: =(SUM(B421:B424))/4 -> 68.835 | Y424: =(SUM(C421:C424))/4 -> 59.3475 | Z424: =(SUM(D421:D424))/4 -> 49.2875 | AA424: =(SUM(E421:E424))/4 -> 34.2375 | AB424: =(SUM(F421:F424))/4 -> 21.43 | AC424: =(B424+C424)/2 -> 64.595 | AD424: =(C424+D424)/2 -> 54.76 | AE424: =(D424+E424)/2 -> 42.33 | AF424: =(E424+F424)/2 -> 28.425 | AK424: =((V424+W424)/2)-5.35 -> 22.7475
A425: =A424+7 -> 43854 | B425: 69.75 | C425: 60.4 | D425: 50.23 | E425: 35.44 | F425: 21.91 | G425: 68.45 | H425: =B425-B424 -> 0.5 | I425: =C425-C424 -> 0.46 | J425: =D425-D424 -> 0.65 | K425: =E425-E424 -> 0.36 | L425: =F425-F424 -> 0.14 | M425: =G425-G424 -> -5.33 | N425: =N424 -> 69.036 | O425: =O424 -> 59.692 | P425: =P424 -> 49.678 | Q425: =Q424 -> 34.808 | R425: =R424 -> 21.608 | S425: =(B424+B425)/2 -> 69.5 | T425: =(C424+C425)/2 -> 60.17 | U425: =(D425+D424)/2 -> 49.905 | V425: =(E424+E425)/2 -> 35.26 | W425: =(F424+F425)/2 -> 21.84 | X425: =(SUM(B422:B425))/4 -> 69.05 | Y425: =(SUM(C422:C425))/4 -> 59.655 | Z425: =(SUM(D422:D425))/4 -> 49.5525 | AA425: =(SUM(E422:E425))/4 -> 34.64 | AB425: =(SUM(F422:F425))/4 -> 21.55 | AC425: =(B425+C425)/2 -> 65.075 | AD425: =(C425+D425)/2 -> 55.315 | AE425: =(D425+E425)/2 -> 42.835 | AF425: =(E425+F425)/2 -> 28.675 | AK425: =((V425+W425)/2)-5.35 -> 23.2
A426: =A425+7 -> 43861 | B426: 68.98 | C426: 59.84 | D426: 50.18 | E426: 35.48 | F426: 21.84 | G426: 66.83 | H426: =B426-B425 -> -0.77 | I426: =C426-C425 -> -0.56 | J426: =D426-D425 -> -0.05 | K426: =E426-E425 -> 0.04 | L426: =F426-F425 -> -0.07 | M426: =G426-G425 -> -1.62 | N426: =N425 -> 69.036 | O426: =O425 -> 59.692 | P426: =P425 -> 49.678 | Q426: =Q425 -> 34.808 | R426: =R425 -> 21.608 | S426: =(B425+B426)/2 -> 69.365 | T426: =(C425+C426)/2 -> 60.12 | U426: =(D426+D425)/2 -> 50.205 | V426: =(E425+E426)/2 -> 35.46 | W426: =(F425+F426)/2 -> 21.875 | X426: =(SUM(B423:B426))/4 -> 69.19 | Y426: =(SUM(C423:C426))/4 -> 59.915 | Z426: =(SUM(D423:D426))/4 -> 49.845 | AA426: =(SUM(E423:E426))/4 -> 35.0675 | AB426: =(SUM(F423:F426))/4 -> 21.6975 | AC426: =(B426+C426)/2 -> 64.41 | AD426: =(C426+D426)/2 -> 55.01 | AE426: =(D426+E426)/2 -> 42.83 | AF426: =(E426+F426)/2 -> 28.66 | AK426: =((V426+W426)/2)-5.35 -> 23.3175
A427: =A426+7 -> 43868 | B427: 69.56 | C427: 60.84 | D427: 51.45 | E427: 36.4 | F427: 22.16 | G427: 66.86 | H427: =B427-B426 -> 0.58 | I427: =C427-C426 -> 1 | J427: =D427-D426 -> 1.27 | K427: =E427-E426 -> 0.92 | L427: =F427-F426 -> 0.32 | M427: =G427-G426 -> 0.03 | N427: =AVERAGE(B427:B430) -> 69.6 | O427: =AVERAGE(C427:C430) -> 60.9925 | P427: =AVERAGE(D427:D430) -> 51.275 | Q427: =AVERAGE(E427:E430) -> 35.9525 | R427: =AVERAGE(F427:F430) -> 22.4475 | S427: =(B426+B427)/2 -> 69.27 | T427: =(C426+C427)/2 -> 60.34 | U427: =(D427+D426)/2 -> 50.815 | V427: =(E426+E427)/2 -> 35.94 | W427: =(F426+F427)/2 -> 22 | X427: =(SUM(B424:B427))/4 -> 69.385 | Y427: =(SUM(C424:C427))/4 -> 60.255 | Z427: =(SUM(D424:D427))/4 -> 50.36 | AA427: =(SUM(E424:E427))/4 -> 35.6 | AB427: =(SUM(F424:F427))/4 -> 21.92 | AC427: =(B427+C427)/2 -> 65.2 | AD427: =(C427+D427)/2 -> 56.145 | AE427: =(D427+E427)/2 -> 43.925 | AF427: =(E427+F427)/2 -> 29.28 | AK427: =((V427+W427)/2)-5.35 -> 23.62
A428: =A427+7 -> 43875 | B428: 69.77 | C428: 61.05 | D428: 51.68 | E428: 36.67 | F428: 22.46 | G428: 69.32 | H428: =B428-B427 -> 0.21 | I428: =C428-C427 -> 0.21 | J428: =D428-D427 -> 0.23 | K428: =E428-E427 -> 0.27 | L428: =F428-F427 -> 0.3 | M428: =G428-G427 -> 2.46 | N428: =N427 -> 69.6 | O428: =O427 -> 60.9925 | P428: =P427 -> 51.275 | Q428: =Q427 -> 35.9525 | R428: =R427 -> 22.4475 | S428: =(B427+B428)/2 -> 69.665 | T428: =(C427+C428)/2 -> 60.945 | U428: =(D428+D427)/2 -> 51.565 | V428: =(E427+E428)/2 -> 36.535 | W428: =(F427+F428)/2 -> 22.31 | X428: =(SUM(B425:B428))/4 -> 69.515 | Y428: =(SUM(C425:C428))/4 -> 60.5325 | Z428: =(SUM(D425:D428))/4 -> 50.885 | AA428: =(SUM(E425:E428))/4 -> 35.9975 | AB428: =(SUM(F425:F428))/4 -> 22.0925 | AC428: =(B428+C428)/2 -> 65.41 | AD428: =(C428+D428)/2 -> 56.365 | AE428: =(D428+E428)/2 -> 44.175 | AF428: =(E428+F428)/2 -> 29.565 | AK428: =((V428+W428)/2)-5.35 -> 24.0725
...

Sheet HPB Calculation
A1: New Formula for coal price from Indonesian Government
A2: The price is minimum price from MINER
A4: HBA Formula (in 1st)
A5: HBA = (0.7*x1) + (0.3*x2) {US$/ton)
A6: X1 | B6: 70% derived from the weighted average FOB vessel sales price from the fourth week two months prior to the first week of the previous month
A7: X2 | B7: 30% from the weighted average FOB vessel sales price during the second and third weeks of two months prior.
A9: HBA Formula (in 15th)
A10: HBA = (0.7*x1) + (0.3*x2) {US$/ton)
A11: X1 | B11: 70% based on the weighted average FOB vessel sales price during the second and third weeks of the previous month.
A12: X2 | B12: 30% from the fourth week two months prior to the first week of the previous month.
A14: Spec | B14: GAR | C14: TM | D14: TS | E14: ASH | F14: Details
A15: HBA 0 | B15: 6322 | C15: 12.26 | D15: 0.66 | E15: 7.94 | F15: > 6000 GAR
A16: HBA I | B16: 5300 | C16: 21.32 | D16: 0.75 | E16: 6.04 | F16: > 5300 GAR - <6000 GAR
A17: HBA II | B17: 4100 | C17: 35.73 | D17: 0.23 | E17: 3.9 | F17: > 4100 GAR - <5,300 GAR
F18: < 4100 GAR - >3400 GAR
A19: HBA III | B19: 3400 | C19: 44.3 | D19: 0.24 | E19: 3.88 | F19: <3400 GAR
A20: HBA 90 | B20: 6322 | C20: 12.26 | D20: 0.66 | E20: 7.94 | F20: Domestic
A22: HBA Price
A23: Month | B23: HBA 0 | C23: HBA I | D23: HBA II | E23: HBA III | F23: Selisih HBA 1 - HBA II
A24: 45658 | B24: 124.24 | C24: 82.26 | D24: 52.75 | E24: 34.38 | F24: =C24-D24 -> 29.51
A25: 45689 | B25: 124.01 | C25: 83.95 | D25: 50.52 | E25: 34.7 | F25: =C25-D25 -> 33.43
A26: 45717 | B26: 128.24 | C26: 82.66 | D26: 50.7 | E26: 34.14 | F26: =C26-D26 -> 31.96
A27: 45731 | B27: 117.76 | C27: 80.7 | D27: 49.44 | E27: 33.17 | F27: =C27-D27 -> 31.26
A28: 45748 | B28: 123.32 | C28: 78.4 | D28: 49.54 | E28: 32.71 | F28: =C28-D28 -> 28.86
A29: 45762 | B29: 120.2 | C29: 78.46 | D29: 50.07 | E29: 34.32 | F29: =C29-D29 -> 28.39
A30: 45778 | B30: 121.15 | C30: 80.8 | D30: 50.43 | E30: 34.73 | F30: =C30-D30 -> 30.37
A31: 45792 | B31: 110.38 | C31: 76.62 | D31: 50.58 | E31: 35.42 | F31: =C31-D31 -> 26.04
A32: 45809 | B32: 100.97 | C32: 77.59 | D32: 50.08 | E32: 35.47
A33: 45823 | B33: 98.61 | C33: 75.64 | D33: 50.25 | E33: 36.14
A34: 45839 | B34: 107.35 | C34: 71.5 | D34: 49.78 | E34: 35.87
A35: 45853 | B35: 97.65 | C35: 75.94 | D35: 48.35 | E35: 36
A36: 45870 | B36: 102.22 | C36: 67.33 | D36: 45.74 | E36: 34.86
A37: 45884 | B37: 100.69 | C37: 67.2 | D37: 43.7 | E37: 33.48
A38: 45901 | B38: 105.33 | C38: 66.5 | D38: 42.3 | E38: 32.32
A39: 45915 | B39: 103.49 | C39: 64.4 | D39: 42.58 | E39: 32.78
A40: 45931 | B40: 106.94 | C40: 64.84 | D40: 43.12 | E40: 32.95
A41: 45945 | B41: 109.74 | C41: 67.76 | D41: 43.71 | E41: 33.92
A42: 45962 | B42: 103.75 | C42: 67.22 | D42: 44.02 | E42: 33.74
A43: 45976 | B43: 102.03 | C43: 67.29 | D43: 44.29 | E43: 33.88
... A50: 46082 | B50: 102.37 | C50: 71.29 | D50: 47.64 | E50: 34.25
...

Sheet HPB
A1: New Formula for coal price from Indonesian Government
A2: The price is minimum price from MINER
A4: HBA Formula (in 1st)
A5: HBA = (0.7*x1) + (0.3*x2) {US$/ton)
A6: X1 | B6: 70% derived from the weighted average FOB vessel sales price from the fourth week two months prior to the first week of the previous month
A7: X2 | B7: 30% from the weighted average FOB vessel sales price during the second and third weeks of two months prior.
A9: HBA Formula (in 15th)
A10: HBA = (0.7*x1) + (0.3*x2) {US$/ton)
A11: X1 | B11: 70% based on the weighted average FOB vessel sales price during the second and third weeks of the previous month.
A12: X2 | B12: 30% from the fourth week two months prior to the first week of the previous month.
A14: Spec | B14: GAR | C14: TM | D14: TS | E14: ASH | F14: Details
A15: HBA 0 | B15: 6322 | C15: 12.26 | D15: 0.66 | E15: 7.94 | F15: > 6000 GAR
A16: HBA I | B16: 5300 | C16: 21.32 | D16: 0.75 | E16: 6.04 | F16: > 5300 GAR - <6000 GAR
A17: HBA II | B17: 4100 | C17: 35.73 | D17: 0.23 | E17: 3.9 | F17: > 4100 GAR - <5,300 GAR
F18: < 4100 GAR - >3400 GAR
A19: HBA III | B19: 3400 | C19: 44.3 | D19: 0.24 | E19: 3.88 | F19: <3400 GAR
A20: HBA 90 | B20: 6322 | C20: 12.26 | D20: 0.66 | E20: 7.94 | F20: Domestic
A22: HBA Price
A23: Month | B23: HBA 0 | C23: HBA I | D23: HBA II | E23: HBA III | F23: HBA 90
A24: 45658 | B24: 124.24 | C24: 82.26 | D24: 52.75 | E24: 34.38 | F24: 124.24
A25: 45689 | B25: 124.01 | C25: 83.95 | D25: 50.52 | E25: 34.7 | F25: 124.01
A26: 45717 | B26: 128.24 | C26: 82.66 | D26: 50.7 | E26: 34.14 | F26: 128.24
A27: 45731 | B27: 117.76 | C27: 80.7 | D27: 49.44 | E27: 33.17 | F27: 117.76
A28: 45748 | B28: 123.32 | C28: 78.4 | D28: 49.54
B29: =B26-B27 -> 10.48
A31: SOURCE | C31: KUALITAS | H31: ARB | I31: ARB | J31: HBA | K31: HBA | L31: HBA*K*TM | M31: FKA | N31: TS + ASH | O31: HPB | P31: FINAL | Q31: ICI | R31: HD | S31: DELTA
C32: GAR | D32: TM (ar, %) | E32: IM | F32: TS ADB | G32: ASH ADB | H32: TS (%) | I32: Ash (%) | J32: Category | K32: Price | P32: HPB SUPPLIER | Q32: PRX | R32: PRX (0.977) | S32: PRX
A33: PTBA | C33: 5000 | D33: 28 | E33: 13 | F33: 0.8 | G33: 8 | H33: =((100-D33)/(100-E33))*F33 -> 0.66206897 | I33: =((100-D33)/(100-E33))*G33 -> 6.6206897 | L33: =D27*(C33/B15)*((100-D33)/(100-C15)) -> 32.08698 | M33: 0 | N33: =((H33-D$15)*4+(I33-E$15)*0.4) -> -0.51944828 | O33: =L33-N33 -> 32.606428 | Q33: =#REF! -> #REF! | R33: =Q33*0.977 -> #REF! | S33: =O33-R33 -> #REF!
A34: MBL | C34: 5280 | D34: 22 | E34: 14 | F34: 1 | G34: 6 | H34: =((100-D34)/(100-E34))*F34 -> 0.90697674 | I34: =((100-D34)/(100-E34))*G34 -> 5.4418605 | L34: =C27*(C34/B16)*((100-D34)/(100-C16)) -> 79.700646 | M34: 0 | N34: =((H34-D$16)*4+(I34-E$16)*0.4) -> 0.38865116 | O34: =L34-N34 -> 79.311994 | Q34: =#REF!*HPB!C34/5800 -> #REF! | R34: =Q34*0.977 -> #REF! | S34: =O34-R34 -> #REF!
A35: BME | C35: 5400 | D35: 25 | E35: 11 | F35: 0.8 | G35: 6 | H35: =((100-D35)/(100-E35))*F35 -> 0.6741573 | I35: =((100-D35)/(100-E35))*G35 -> 5.0561798 | L35: =C27*(C35/B16)*((100-D35)/(100-C16)) -> 78.376946 | M35: 0 | N35: =((H35-D$16)*4+(I35-E$16)*0.4) -> -0.69689888 | O35: =L35-N35 -> 79.073845 | Q35: =#REF!*HPB!C35/5800 -> #REF! | R35: =Q35*0.977 -> #REF! | S35: =O35-R35 -> #REF!
A36: KMIA
A37: MCM | C37: 4600 | D37: 32 | E37: 18 | F37: 0.3 | G37: 6 | H37: =((100-D37)/(100-E37))*F37 -> 0.24878049 | I37: =((100-D37)/(100-E37))*G37 -> 4.9756098 | L37: =D27*(C37/B17)*((100-D37)/(100-C17)) -> 58.688505 | M37: 0 | N37: =((H37-D$19)*4+(I37-E$19)*0.4) -> 0.47336585 | O37: =L37-N37 -> 58.21514
A38: Mind ID 5000 // contract | C38: 5000 | D38: 28 | E38: 13 | F38: 0.8 | G38: 8 | H38: =((100-D38)/(100-E38))*F38 -> 0.66206897 | I38: =((100-D38)/(100-E38))*G38 -> 6.6206897

Sheet HD 5000
A1: Spec | B1: GAR | C1: TM | D1: TS | E1: ASH | F1: Details
A2: HBA 0 | B2: 6322 | C2: 12.26 | D2: 0.66 | E2: 7.94 | F2: > 6000 GAR
A3: HBA I | B3: 5300 | C3: 21.32 | D3: 0.75 | E3: 6.04 | F3: > 5300 GAR - <6000 GAR
A4: HBA II | B4: 4100 | C4: 35.73 | D4: 0.23 | E4: 3.9 | F4: > 4100 GAR - <5,300 GAR
F5: < 4100 GAR - >3400 GAR
B6: 3400 | C6: 44.3 | D6: 0.24 | E6: 3.88 | F6: > 4100 GAR - <5,300 GAR | V6: ICI 0.977 (50%)
B7: 6322 | C7: 12.26 | D7: 0.66 | E7: 7.94 | F7: Domestic | Q7: ICI 0.977 | S7: NEWC 0.707 | V7: NEWC 0.707 (50%)
A8: MONTH | B8: PRICE HBA | C8: ICI 1 | D8: KUALITAS | I8: ARB | J8: ARB | K8: HBA*K*TM | L8: FKA | M8: TS + ASH | N8: HPB | O8: ICI 3 | P8: GAP | Q8: HD | R8: GAP ICI | S8: NEWC | T8: NEWC & DISC | U8: GAP NEWC | V8: HD PRICE (2) | W8: DES PRICE | X8: GAP ICI&NEW
C9: 6500 | D9: GAR | E9: TM (ar, %) | F9: IM | G9: TS ADB | H9: ASH ADB | I9: TS (%) | J9: Ash (%) | N9: =D10 -> 5000 | O9: 5000 | P9: DELTA | Q9: PRICE | R9: DELTA | S9: 6000 | T9: 5000 | U9: DELTA | W9: 23.5 | X9: DELTA
A10: Jan-15 | B10: 63.84 | C10: 65.476 | D10: 5000 | E10: 28 | F10: 13 | G10: 0.8 | H10: 8 | I10: =((100-E10)/(100-F10))*G10 -> 0.66206897 | J10: =((100-E10)/(100-F10))*H10 -> 6.6206897 | K10: =B10*(D10/$B$2)*((100-E10)/(100-$C$2)) -> 41.432702 | L10: 0 | M10: =((I10-$D$2)*4+(J10-$E$2)*0.4) -> -0.51944828 | N10: =K10-M10 -> 41.95215 | O10: 48.38 | P10: =O10-N10 -> 6.4278496 | Q10: =O10*0.9777 -> 47.301126 | R10: =Q10-N10 -> 5.3489756 | S10: 62.802 | T10: =(S10*$T$9/$S$9)*0.707 -> 37.000845 | U10: =T10-N10 -> -4.9513054 | V10: =(O10*0.5)+(T10*0.5) -> 42.690422 | W10: =V10+$W$9 -> 66.190422 | X10: =V10-N10 -> 0.73827211
A11: Feb-15 | B11: 62.92 | C11: 68.125 | D11: =D10 -> 5000 | E11: =E10 -> 28 | F11: =F10 -> 13 | G11: =G10 -> 0.8 | H11: =H10 -> 8 | I11: =((100-E11)/(100-F11))*G11 -> 0.66206897 | J11: =((100-E11)/(100-F11))*H11 -> 6.6206897 | K11: =B11*(D11/$B$2)*((100-E11)/(100-$C$2)) -> 40.835614 | L11: 0 | M11: =((I11-$D$2)*4+(J11-$E$2)*0.4) -> -0.51944828 | N11: =K11-M11 -> 41.355063 | O11: 48.7575 | P11: =O11-N11 -> 7.4024374 | Q11: =O11*0.9777 -> 47.670208 | R11: =Q11-N11 -> 6.3151452 | S11: 71.775 | T11: =(S11*$T$9/$S$9)*0.707 -> 42.287437 | U11: =T11-N11 -> 0.93237493 | V11: =(O11*0.5)+(T11*0.5) -> 45.522469 | W11: =V11+$W$9 -> 69.022469 | X11: =V11-N11 -> 4.1674062
A12: Mar-15 | B12: 67.76 | C12: 67.845 | D12: =D11 -> 5000 | E12: =E11 -> 28 | F12: =F11 -> 13 | G12: =G11 -> 0.8 | H12: =H11 -> 8 | I12: =((100-E12)/(100-F12))*G12 -> 0.66206897 | J12: =((100-E12)/(100-F12))*H12 -> 6.6206897 | K12: =B12*(D12/$B$2)*((100-E12)/(100-$C$2)) -> 43.976815 | L12: 0 | M12: =((I12-$D$2)*4+(J12-$E$2)*0.4) -> -0.51944828 | N12: =K12-M12 -> 44.496264 | O12: 48.43 | P12: =O12-N12 -> 3.9337363 | Q12: =O12*0.9777 -> 47.350011 | R12: =Q12-N12 -> 2.8537473 | S12: 62.87 | T12: =(S12*$T$9/$S$9)*0.707 -> 37.040908 | U12: =T12-N12 -> -7.4553553 | V12: =(O12*0.5)+(T12*0.5) -> 42.735454 | W12: =V12+$W$9 -> 66.235454 | X12: =V12-N12 -> -1.7608095
A13: Apr-15 | B13: 64.48 | C13: 64.2575 | D13: =D12 -> 5000 | E13: =E12 -> 28 | F13: =F12 -> 13 | G13: =G12 -> 0.8 | H13: =H12 -> 8 | I13: =((100-E13)/(100-F13))*G13 -> 0.66206897 | J13: =((100-E13)/(100-F13))*H13 -> 6.6206897 | K13: =B13*(D13/$B$2)*((100-E13)/(100-$C$2)) -> 41.848068 | L13: 0 | M13: =((I13-$D$2)*4+(J13-$E$2)*0.4) -> -0.51944828 | N13: =K13-M13 -> 42.367516 | O13: 47.45 | P13: =O13-N13 -> 5.0824842 | Q13: =O13*0.9777 -> 46.391865 | R13: =Q13-N13 -> 4.0243492 | S13: 58.5475 | T13: =(S13*$T$9/$S$9)*0.707 -> 34.494235 | U13: =T13-N13 -> -7.8732804 | V13: =(O13*0.5)+(T13*0.5) -> 40.972118 | W13: =V13+$W$9 -> 64.472118 | X13: =V13-N13 -> -1.3953981
A14: May-15 | B14: 61.08 | C14: 63.126 | D14: =D13 -> 5000 | E14: =E13 -> 28 | F14: =F13 -> 13 | G14: =G13 -> 0.8 | H14: =H13 -> 8 | I14: =((100-E14)/(100-F14))*G14 -> 0.66206897 | J14: =((100-E14)/(100-F14))*H14 -> 6.6206897 | K14: =B14*(D14/$B$2)*((100-E14)/(100-$C$2)) -> 39.641439 | L14: 0 | M14: =((I14-$D$2)*4+(J14-$E$2)*0.4) -> -0.51944828 | N14: =K14-M14 -> 40.160887 | O14: 45.694 | P14: =O14-N14 -> 5.5331131 | Q14: =O14*0.9777 -> 44.675024 | R14: =Q14-N14 -> 4.5141369 | S14: 60.066 | T14: =(S14*$T$9/$S$9)*0.707 -> 35.388885 | U14: =T14-N14 -> -4.7720019 | V14: =(O14*0.5)+(T14*0.5) -> 40.541443 | W14: =V14+$W$9 -> 64.041443 | X14: =V14-N14 -> 0.38055555
A15: Jun-15 | B15: 59.59 | C15: 62.135 | D15: =D14 -> 5000 | E15: =E14 -> 28 | F15: =F14 -> 13 | G15: =G14 -> 0.8 | H15: =H14 -> 8 | I15: =((100-E15)/(100-F15))*G15 -> 0.66206897 | J15: =((100-E15)/(100-F15))*H15 -> 6.6206897 | K15: =B15*(D15/$B$2)*((100-E15)/(100-$C$2)) -> 38.674416 | L15: 0 | M15: =((I15-$D$2)*4+(J15-$E$2)*0.4) -> -0.51944828 | N15: =K15-M15 -> 39.193864 | O15: 43.3325 | P15: =O15-N15 -> 4.1386357 | Q15: =O15*0.9777 -> 42.366185 | R15: =Q15-N15 -> 3.172321 | S15: 60.0975 | T15: =(S15*$T$9/$S$9)*0.707 -> 35.407444 | U15: =T15-N15 -> -3.7864205 | V15: =(O15*0.5)+(T15*0.5) -> 39.369972 | W15: =V15+$W$9 -> 62.869972 | X15: =V15-N15 -> 0.17610758
A16: Jul-15 | B16: 59.19 | C16: 61.262 | D16: =D15 -> 5000 | E16: =E15 -> 28 | F16: =F15 -> 13 | G16: =G15 -> 0.8 | H16: =H15 -> 8 | I16: =((100-E16)/(100-F16))*G16 -> 0.66206897 | J16: =((100-E16)/(100-F16))*H16 -> 6.6206897 | K16: =B16*(D16/$B$2)*((100-E16)/(100-$C$2)) -> 38.414813 | L16: 0 | M16: =((I16-$D$2)*4+(J16-$E$2)*0.4) -> -0.51944828 | N16: =K16-M16 -> 38.934261 | O16: 41.81 | P16: =O16-N16 -> 2.8757391 | Q16: =O16*0.9777 -> 40.877637 | R16: =Q16-N16 -> 1.9433761 | S16: 60.346 | T16: =(S16*$T$9/$S$9)*0.707 -> 35.553852 | U16: =T16-N16 -> -3.3804092 | V16: =(O16*0.5)+(T16*0.5) -> 38.681926 | W16: =V16+$W$9 -> 62.181926 | X16: =V16-N16 -> -0.25233507
A17: Aug-15 | B17: 59.14 | C17: 60.5925 | D17: =D16 -> 5000 | E17: =E16 -> 28 | F17: =F16 -> 13 | G17: =G16 -> 0.8 | H17: =H16 -> 8 | I17: =((100-E17)/(100-F17))*G17 -> 0.66206897 | J17: =((100-E17)/(100-F17))*H17 -> 6.6206897 | K17: =B17*(D17/$B$2)*((100-E17)/(100-$C$2)) -> 38.382362 | L17: 0 | M17: =((I17-$D$2)*4+(J17-$E$2)*0.4) -> -0.51944828 | N17: =K17-M17 -> 38.90181 | O17: 41.195 | P17: =O17-N17 -> 2.2931895 | Q17: =O17*0.9777 -> 40.276352 | R17: =Q17-N17 -> 1.374541 | S17: 58.6025 | T17: =(S17*$T$9/$S$9)*0.707 -> 34.52664 | U17: =T17-N17 -> -4.3751709 | V17: =(O17*0.5)+(T17*0.5) -> 37.86082 | W17: =V17+$W$9 -> 61.36082 | X17: =V17-N17 -> -1.0409907
A18: Sep-15 | B18: 58.21 | C18: 60.9025 | D18: =D17 -> 5000 | E18: =E17 -> 28 | F18: =F17 -> 13 | G18: =G17 -> 0.8 | H18: =H17 -> 8 | I18: =((100-E18)/(100-F18))*G18 -> 0.66206897 | J18: =((100-E18)/(100-F18))*H18 -> 6.6206897 | K18: =B18*(D18/$B$2)*((100-E18)/(100-$C$2)) -> 37.778784 | L18: 0 | M18: =((I18-$D$2)*4+(J18-$E$2)*0.4) -> -0.51944828 | N18: =K18-M18 -> 38.298233 | O18: 40.9175 | P18: =O18-N18 -> 2.6192674 | Q18: =O18*0.9777 -> 40.00504 | R18: =Q18-N18 -> 1.7068072 | S18: 57.585 | T18: =(S18*$T$9/$S$9)*0.707 -> 33.927162 | U18: =T18-N18 -> -4.3710701 | V18: =(O18*0.5)+(T18*0.5) -> 37.422331 | W18: =V18+$W$9 -> 60.922331 | X18: =V18-N18 -> -0.87590133
A19: Oct-15 | B19: 57.39 | C19: 60.178 | D19: =D18 -> 5000 | E19: =E18 -> 28 | F19: =F18 -> 13 | G19: =G18 -> 0.8 | H19: =H18 -> 8 | I19: =((100-E19)/(100-F19))*G19 -> 0.66206897 | J19: =((100-E19)/(100-F19))*H19 -> 6.6206897 | K19: =B19*(D19/$B$2)*((100-E19)/(100-$C$2)) -> 37.246597 | L19: 0 | M19: =((I19-$D$2)*4+(J19-$E$2)*0.4) -> -0.51944828 | N19: =K19-M19 -> 37.766046 | O19: 39.32 | P19: =O19-N19 -> 1.5539544 | Q19: =O19*0.9777 -> 38.443164 | R19: =Q19-N19 -> 0.67711839 | S19: 52.972 | T19: =(S19*$T$9/$S$9)*0.707 -> 31.209337 | U19: =T19-N19 -> -6.5567089 | V19: =(O19*0.5)+(T19*0.5) -> 35.264668 | W19: =V19+$W$9 -> 58.764668 | X19: =V19-N19 -> -2.5013773
A20: Nov-15 | B20: 54.43 | C20: 59.22 | D20: =D19 -> 5000 | E20: =E19 -> 28 | F20: =F19 -> 13 | G20: =G19 -> 0.8 | H20: =H19 -> 8 | I20: =((100-E20)/(100-F20))*G20 -> 0.66206897 | J20: =((100-E20)/(100-F20))*H20 -> 6.6206897 | K20: =B20*(D20/$B$2)*((100-E20)/(100-$C$2)) -> 35.325532 | L20: 0 | M20: =((I20-$D$2)*4+(J20-$E$2)*0.4) -> -0.51944828 | N20: =K20-M20 -> 35.84498 | O20: 38.3275 | P20: =O20-N20 -> 2.4825195 | Q20: =O20*0.9777 -> 37.472797 | R20: =Q20-N20 -> 1.6278163 | S20: 52.7575 | T20: =(S20*$T$9/$S$9)*0.707 -> 31.08296 | U20: =T20-N20 -> -4.7620201 | V20: =(O20*0.5)+(T20*0.5) -> 34.70523 | W20: =V20+$W$9 -> 58.20523 | X20: =V20-N20 -> -1.1397503
A21: Dec-15 | B21: 53.51 | C21: 58.7 | D21: =D20 -> 5000 | E21: =E20 -> 28 | F21: =F20 -> 13 | G21: =G20 -> 0.8 | H21: =H20 -> 8 | I21: =((100-E21)/(100-F21))*G21 -> 0.66206897 | J21: =((100-E21)/(100-F21))*H21 -> 6.6206897 | K21: =B21*(D21/$B$2)*((100-E21)/(100-$C$2)) -> 34.728444 | L21: 0 | M21: =((I21-$D$2)*4+(J21-$E$2)*0.4) -> -0.51944828 | N21: =K21-M21 -> 35.247893 | O21: 38.335 | P21: =O21-N21 -> 3.0871073 | Q21: =O21*0.9777 -> 37.48013 | R21: =Q21-N21 -> 2.2322368 | S21: 51.9575 | T21: =(S21*$T$9/$S$9)*0.707 -> 30.611627 | U21: =T21-N21 -> -4.6362656 | V21: =(O21*0.5)+(T21*0.5) -> 34.473314 | W21: =V21+$W$9 -> 57.973314 | X21: =V21-N21 -> -0.77457913
A22: Jan-16 | B22: 53.2 | C22: 57.956 | D22: =D21 -> 5000 | E22: =E21 -> 28 | F22: =F21 -> 13 | G22: =G21 -> 0.8 | H22: =H21 -> 8 | I22: =((100-E22)/(100-F22))*G22 -> 0.66206897 | J22: =((100-E22)/(100-F22))*H22 -> 6.6206897 | K22: =B22*(D22/$B$2)*((100-E22)/(100-$C$2)) -> 34.527252 | L22: 0 | M22: =((I22-$D$2)*4+(J22-$E$2)*0.4) -> -0.51944828 | N22: =K22-M22 -> 35.0467 | O22: 37.786 | P22: =O22-N22 -> 2.7393 | Q22: =O22*0.9777 -> 36.943372 | R22: =Q22-N22 -> 1.8966722 | S22: 48.802 | T22: =(S22*$T$9/$S$9)*0.707 -> 28.752512 | U22: =T22-N22 -> -6.2941884 | V22: =(O22*0.5)+(T22*0.5) -> 33.269256 | W22: =V22+$W$9 -> 56.769256 | X22: =V22-N22 -> -1.7774442
... A55: Oct-18 | B55: 100.89 | C55: 97.81 | D55: =D54 -> 5000 | E55: =E54 -> 28 | F55: =F54 -> 13 | G55: =G54 -> 0.8 | H55: =H54 -> 8 | I55: =((100-E55)/(100-F55))*G55 -> 0.66206897 | J55: =((100-E55)/(100-F55))*H55 -> 6.6206897 | K55: =B55*(D55/$B$2)*((100-E55)/(100-$C$2)) -> 65.478467 | L55: 0 | M55: =((I55-$D$2)*4+(J55-$E$2)*0.4) -> -0.51944828 | N55: =K55-M55 -> 65.997915 | O55: 52.8375 | P55: =O55-N55 -> -13.160415 | Q55: =O55*0.9777 -> 51.659224 | R55: =Q55-N55 -> -14.338691 | S55: 109.5175 | T55: =(S55*$T$9/$S$9)*0.707 -> 64.52406 | U55: =T55-N55 -> -1.4738546 | V55: =(O55*0.5)+(T55*0.5) -> 58.68078 | W55: =V55+$W$9 -> 82.18078 | X55: =V55-N55 -> -7.3171348
A56: 43422 | B56: 97.9 | C56: 95.016 | D56: =D55 -> 5000 | E56: =E55 -> 28 | F56: =F55 -> 13 | G56: =G55 -> 0.8 | H56: =H55 -> 8 | I56: =((100-E56)/(100-F56))*G56 -> 0.66206897 | J56: =((100-E56)/(100-F56))*H56 -> 6.6206897 | K56: =B56*(D56/$B$2)*((100-E56)/(100-$C$2)) -> 63.537931 | L56: 0 | M56: =((I56-$D$2)*4+(J56-$E$2)*0.4) -> -0.51944828 | N56: =K56-M56 -> 64.05738 | O56: 49.612 | P56: =O56-N56 -> -14.44538 | Q56: =O56*0.9777 -> 48.505652 | R56: =Q56-N56 -> -15.551727 | S56: 101.808 | T56: =(S56*$T$9/$S$9)*0.707 -> 59.98188 | U56: =T56-N56 -> -4.0754996 | V56: =(O56*0.5)+(T56*0.5) -> 54.79694 | W56: =V56+$W$9 -> 78.29694 | X56: =V56-N56 -> -9.2604396
A57: Dec-18 | B57: 92.51 | C57: 94.28 | D57: =D56 -> 5000 | E57: =E56 -> 28 | F57: =F56 -> 13 | G57: =G56 -> 0.8 | H57: =H56 -> 8 | I57: =((100-E57)/(100-F57))*G57 -> 0.66206897 | J57: =((100-E57)/(100-F57))*H57 -> 6.6206897 | K57: =B57*(D57/$B$2)*((100-E57)/(100-$C$2)) -> 60.039776 | L57: 0 | M57: =((I57-$D$2)*4+(J57-$E$2)*0.4) -> -0.51944828 | N57: =K57-M57 -> 60.559224 | O57: 46.695 | P57: =O57-N57 -> -13.864224 | Q57: =O57*0.9777 -> 45.653702 | R57: =Q57-N57 -> -14.905522 | S57: 101.865 | T57: =(S57*$T$9/$S$9)*0.707 -> 60.015462 | U57: =T57-N57 -> -0.54376134 | V57: =(O57*0.5)+(T57*0.5) -> 53.355231 | W57: =V57+$W$9 -> 76.855231 | X57: =V57-N57 -> -7.2039926
A58: Jan-19 | B58: 92.41 | C58: 97.0475 | D58: =D57 -> 5000 | E58: =E57 -> 28 | F58: =F57 -> 13 | G58: =G57 -> 0.8 | H58: =H57 -> 8 | I58: =((100-E58)/(100-F58))*G58 -> 0.66206897 | J58: =((100-E58)/(100-F58))*H58 -> 6.6206897 | K58: =B58*(D58/$B$2)*((100-E58)/(100-$C$2)) -> 59.974875 | L58: 0 | M58: =((I58-$D$2)*4+(J58-$E$2)*0.4) -> -0.51944828 | N58: =K58-M58 -> 60.494323 | O58: 49.01 | P58: =O58-N58 -> -11.484323 | Q58: =O58*0.9777 -> 47.917077 | R58: =Q58-N58 -> -12.577246 | S58: 99.0575 | T58: =(S58*$T$9/$S$9)*0.707 -> 58.361377 | U58: =T58-N58 -> -2.1329459 | V58: =(O58*0.5)+(T58*0.5) -> 53.685689 | W58: =V58+$W$9 -> 77.185689 | X58: =V58-N58 -> -6.8086345
A59: Feb-19 | B59: 91.8 | C59: 96.8725 | D59: =D58 -> 5000 | E59: =E58 -> 28 | F59: =F58 -> 13 | G59: =G58 -> 0.8 | H59: =H58 -> 8 | I59: =((100-E59)/(100-F59))*G59 -> 0.66206897 | J59: =((100-E59)/(100-F59))*H59 -> 6.6206897 | K59: =B59*(D59/$B$2)*((100-E59)/(100-$C$2)) -> 59.57898 | L59: 0 | M59: =((I59-$D$2)*4+(J59-$E$2)*0.4) -> -0.51944828 | N59: =K59-M59 -> 60.098428 | O59: 54.085 | P59: =O59-N59 -> -6.0134278 | Q59: =O59*0.9777 -> 52.878904 | R59: =Q59-N59 -> -7.2195233 | S59: 95.4425 | T59: =(S59*$T$9/$S$9)*0.707 -> 56.23154 | U59: =T59-N59 -> -3.8668882 | V59: =(O59*0.5)+(T59*0.5) -> 55.15827 | W59: =V59+$W$9 -> 78.65827 | X59: =V59-N59 -> -4.940158
A60: Mar-19 | B60: 90.57 | C60: 94.85 | D60: =D59 -> 5000 | E60: =E59 -> 28 | F60: =F59 -> 13 | G60: =G59 -> 0.8 | H60: =H59 -> 8 | I60: =((100-E60)/(100-F60))*G60 -> 0.66206897 | J60: =((100-E60)/(100-F60))*H60 -> 6.6206897 | K60: =B60*(D60/$B$2)*((100-E60)/(100-$C$2)) -> 58.780699 | L60: 0 | M60: =((I60-$D$2)*4+(J60-$E$2)*0.4) -> -0.51944828 | N60: =K60-M60 -> 59.300147 | O60: 56.076 | P60: =O60-N60 -> -3.2241474 | Q60: =O60*0.9777 -> 54.825505 | R60: =Q60-N60 -> -4.4746422 | S60: 93.134 | T60: =(S60*$T$9/$S$9)*0.707 -> 54.871448 | U60: =T60-N60 -> -4.428699 | V60: =(O60*0.5)+(T60*0.5) -> 55.473724 | W60: =V60+$W$9 -> 78.973724 | X60: =V60-N60 -> -3.8264232
A61: Apr-19 | B61: 88.85 | C61: 85.4225 | D61: =D60 -> 5000 | E61: =E60 -> 28 | F61: =F60 -> 13 | G61: =G60 -> 0.8 | H61: =H60 -> 8 | I61: =((100-E61)/(100-F61))*G61 -> 0.66206897 | J61: =((100-E61)/(100-F61))*H61 -> 6.6206897 | K61: =B61*(D61/$B$2)*((100-E61)/(100-$C$2)) -> 57.664404 | L61: 0 | M61: =((I61-$D$2)*4+(J61-$E$2)*0.4) -> -0.51944828 | N61: =K61-M61 -> 58.183853 | O61: 52.9775 | P61: =O61-N61 -> -5.2063528 | Q61: =O61*0.9777 -> 51.796102 | R61: =Q61-N61 -> -6.387751 | S61: 85.3225 | T61: =(S61*$T$9/$S$9)*0.707 -> 50.269173 | U61: =T61-N61 -> -7.9146798 | V61: =(O61*0.5)+(T61*0.5) -> 51.623336 | W61: =V61+$W$9 -> 75.123336 | X61: =V61-N61 -> -6.5605163
A62: May-19 | B62: 81.86 | C62: 83.388 | D62: =D61 -> 5000 | E62: =E61 -> 28 | F62: =F61 -> 13 | G62: =G61 -> 0.8 | H62: =H61 -> 8 | I62: =((100-E62)/(100-F62))*G62 -> 0.66206897 | J62: =((100-E62)/(100-F62))*H62 -> 6.6206897 | K62: =B62*(D62/$B$2)*((100-E62)/(100-$C$2)) -> 53.127835 | L62: 0 | M62: =((I62-$D$2)*4+(J62-$E$2)*0.4) -> -0.51944828 | N62: =K62-M62 -> 53.647283 | O62: 52.606 | P62: =O62-N62 -> -1.0412834 | Q62: =O62*0.9777 -> 51.432886 | R62: =Q62-N62 -> -2.2143972 | S62: 83.756 | T62: =(S62*$T$9/$S$9)*0.707 -> 49.346243 | U62: =T62-N62 -> -4.3010401 | V62: =(O62*0.5)+(T62*0.5) -> 50.976122 | W62: =V62+$W$9 -> 74.476122 | X62: =V62-N62 -> -2.6711617
A63: Jun-19 | B63: 81.48 | C63: 75.73 | D63: =D62 -> 5000 | E63: =E62 -> 28 | F63: =F62 -> 13 | G63: =G62 -> 0.8 | H63: =H62 -> 8 | I63: =((100-E63)/(100-F63))*G63 -> 0.66206897 | J63: =((100-E63)/(100-F63))*H63 -> 6.6206897 | K63: =B63*(D63/$B$2)*((100-E63)/(100-$C$2)) -> 52.881212 | L63: 0 | M63: =((I63-$D$2)*4+(J63-$E$2)*0.4) -> -0.51944828 | N63: =K63-M63 -> 53.40066 | O63: 49.62 | P63: =O63-N63 -> -3.7806602 | Q63: =O63*0.9777 -> 48.513474 | R63: =Q63-N63 -> -4.8871862 | S63: 71.1125 | T63: =(S63*$T$9/$S$9)*0.707 -> 41.897115 | U63: =T63-N63 -> -11.503546 | V63: =(O63*0.5)+(T63*0.5) -> 45.758557 | W63: =V63+$W$9 -> 69.258557 | X63: =V63-N63 -> -7.6421029
A64: Jul-19 | B64: 71.92 | C64: 74.2525 | D64: =D63 -> 5000 | E64: =E63 -> 28 | F64: =F63 -> 13 | G64: =G63 -> 0.8 | H64: =H63 -> 8 | I64: =((100-E64)/(100-F64))*G64 -> 0.66206897 | J64: =((100-E64)/(100-F64))*H64 -> 6.6206897 | K64: =B64*(D64/$B$2)*((100-E64)/(100-$C$2)) -> 46.676691 | L64: 0 | M64: =((I64-$D$2)*4+(J64-$E$2)*0.4) -> -0.51944828 | N64: =K64-M64 -> 47.196139 | O64: 48.995 | P64: =O64-N64 -> 1.798861 | Q64: =O64*0.9777 -> 47.902411 | R64: =Q64-N64 -> 0.7062725 | S64: 73.9625 | T64: =(S64*$T$9/$S$9)*0.707 -> 43.57624 | U64: =T64-N64 -> -3.6198994 | V64: =(O64*0.5)+(T64*0.5) -> 46.28562 | W64: =V64+$W$9 -> 69.78562 | X64: =V64-N64 -> -0.91051921
A65: Aug-19 | B65: 72.67 | C65: 69.266 | D65: =D64 -> 5000 | E65: =E64 -> 28 | F65: =F64 -> 13 | G65: =G64 -> 0.8 | H65: =H64 -> 8 | I65: =((100-E65)/(100-F65))*G65 -> 0.66206897 | J65: =((100-E65)/(100-F65))*H65 -> 6.6206897 | K65: =B65*(D65/$B$2)*((100-E65)/(100-$C$2)) -> 47.163447 | L65: 0 | M65: =((I65-$D$2)*4+(J65-$E$2)*0.4) -> -0.51944828 | N65: =K65-M65 -> 47.682895 | O65: 47.224 | P65: =O65-N65 -> -0.45889537 | Q65: =O65*0.9777 -> 46.170905 | R65: =Q65-N65 -> -1.5119906 | S65: 65.128 | T65: =(S65*$T$9/$S$9)*0.707 -> 38.371247 | U65: =T65-N65 -> -9.3116487 | V65: =(O65*0.5)+(T65*0.5) -> 42.797623 | W65: =V65+$W$9 -> 66.297623 | X65: =V65-N65 -> -4.885272
A66: Sep-19 | C66: 67.7575 | D66: =D65 -> 5000 | E66: =E65 -> 28 | F66: =F65 -> 13 | G66: =G65 -> 0.8 | H66: =H65 -> 8 | I66: =((100-E66)/(100-F66))*G66 -> 0.66206897 | J66: =((100-E66)/(100-F66))*H66 -> 6.6206897 | K66: =B66*(D66/$B$2)*((100-E66)/(100-$C$2)) -> 0 | L66: 0 | M66: =((I66-$D$2)*4+(J66-$E$2)*0.4) -> -0.51944828 | N66: =K66-M66 -> 0.51944828 | O66: 46.9725 | P66: =O66-N66 -> 46.453052 | Q66: =O66*0.9777 -> 45.925013 | R66: =Q66-N66 -> 45.405565 | S66: 65.5 | T66: =(S66*$T$9/$S$9)*0.707 -> 38.590417 | U66: =T66-N66 -> 38.070968 | V66: =(O66*0.5)+(T66*0.5) -> 42.781458 | W66: =V66+$W$9 -> 66.281458 | X66: =V66-N66 -> 42.26201
A67: Oct-19 | C67: 69.5425 | D67: =D66 -> 5000 | E67: =E66 -> 28 | F67: =F66 -> 13 | G67: =G66 -> 0.8 | H67: =H66 -> 8 | I67: =((100-E67)/(100-F67))*G67 -> 0.66206897 | J67: =((100-E67)/(100-F67))*H67 -> 6.6206897 | K67: =B67*(D67/$B$2)*((100-E67)/(100-$C$2)) -> 0 | L67: 0 | M67: =((I67-$D$2)*4+(J67-$E$2)*0.4) -> -0.51944828 | N67: =K67-M67 -> 0.51944828 | O67: 48.53 | P67: =O67-N67 -> 48.010552 | Q67: =O67*0.9777 -> 47.447781 | R67: =Q67-N67 -> 46.928333 | S67: 67.1125 | T67: =(S67*$T$9/$S$9)*0.707 -> 39.540448 | U67: =T67-N67 -> 39.021 | V67: =(O67*0.5)+(T67*0.5) -> 44.035224 | W67: =V67+$W$9 -> 67.535224 | X67: =V67-N67 -> 43.515776
A68: Nov-19 | C68: 69.58 | D68: =D67 -> 5000 | E68: =E67 -> 28 | F68: =F67 -> 13 | G68: =G67 -> 0.8 | H68: =H67 -> 8 | I68: =((100-E68)/(100-F68))*G68 -> 0.66206897 | J68: =((100-E68)/(100-F68))*H68 -> 6.6206897 | K68: =B68*(D68/$B$2)*((100-E68)/(100-$C$2)) -> 0 | L68: 0 | M68: =((I68-$D$2)*4+(J68-$E$2)*0.4) -> -0.51944828 | N68: =K68-M68 -> 0.51944828 | O68: 49.3 | P68: =O68-N68 -> 48.780552 | Q68: =O68*0.9777 -> 48.20061 | R68: =Q68-N68 -> 47.681162 | S68: 67.77 | T68: =(S68*$T$9/$S$9)*0.707 -> 39.927825 | U68: =T68-N68 -> 39.408377 | V68: =(O68*0.5)+(T68*0.5) -> 44.613912 | W68: =V68+$W$9 -> 68.113912 | X68: =V68-N68 -> 44.094464
A69: Dec-19 | C69: 69.1325 | D69: =D68 -> 5000 | E69: =E68 -> 28 | F69: =F68 -> 13 | G69: =G68 -> 0.8 | H69: =H68 -> 8 | I69: =((100-E69)/(100-F69))*G69 -> 0.66206897 | J69: =((100-E69)/(100-F69))*H69 -> 6.6206897 | K69: =B69*(D69/$B$2)*((100-E69)/(100-$C$2)) -> 0 | L69: 0 | M69: =((I69-$D$2)*4+(J69-$E$2)*0.4) -> -0.51944828 | N69: =K69-M69 -> 0.51944828 | O69: 49.465 | P69: =O69-N69 -> 48.945552 | Q69: =O69*0.9777 -> 48.361931 | R69: =Q69-N69 -> 47.842482 | S69: 66.5825 | T69: =(S69*$T$9/$S$9)*0.707 -> 39.22819 | U69: =T69-N69 -> 38.708741 | V69: =(O69*0.5)+(T69*0.5) -> 44.346595 | W69: =V69+$W$9 -> 67.846595 | X69: =V69-N69 -> 43.827147
A70: 43831 | C70: 69.036 | D70: =D69 -> 5000 | E70: =E69 -> 28 | F70: =F69 -> 13 | G70: =G69 -> 0.8 | H70: =H69 -> 8 | I70: =((100-E70)/(100-F70))*G70 -> 0.66206897 | J70: =((100-E70)/(100-F70))*H70 -> 6.6206897 | K70: =B70*(D70/$B$2)*((100-E70)/(100-$C$2)) -> 0 | L70: 0 | M70: =((I70-$D$2)*4+(J70-$E$2)*0.4) -> -0.51944828 | N70: =K70-M70 -> 0.51944828 | O70: 49.678 | P70: =O70-N70 -> 49.158552 | Q70: =O70*0.9777 -> 48.570181 | R70: =Q70-N70 -> 48.050732 | S70: 68.506 | T70: =(S70*$T$9/$S$9)*0.707 -> 40.361452 | U70: =T70-N70 -> 39.842003 | V70: =(O70*0.5)+(T70*0.5) -> 45.019726 | W70: =V70+$W$9 -> 68.519726 | X70: =V70-N70 -> 44.500278
A71: 43862 | C71: 69.6 | D71: =D70 -> 5000 | E71: =E70 -> 28 | F71: =F70 -> 13 | G71: =G70 -> 0.8 | H71: =H70 -> 8 | I71: =((100-E71)/(100-F71))*G71 -> 0.66206897 | J71: =((100-E71)/(100-F71))*H71 -> 6.6206897 | K71: =B71*(D71/$B$2)*((100-E71)/(100-$C$2)) -> 0 | L71: 0 | M71: =((I71-$D$2)*4+(J71-$E$2)*0.4) -> -0.51944828 | N71: =K71-M71 -> 0.51944828 | O71: 51.275 | P71: =O71-N71 -> 50.755552 | Q71: =O71*0.9777 -> 50.131568 | R71: =Q71-N71 -> 49.612119 | S71: 67.79 | T71: =(S71*$T$9/$S$9)*0.707 -> 39.939608 | U71: =T71-N71 -> 39.42016 | V71: =(O71*0.5)+(T71*0.5) -> 45.607304 | W71: =V71+$W$9 -> 69.107304 | X71: =V71-N71 -> 45.087856
A72: 43891 | C72: 67.7525 | D72: =D71 -> 5000 | E72: =E71 -> 28 | F72: =F71 -> 13 | G72: =G71 -> 0.8 | H72: =H71 -> 8 | I72: =((100-E72)/(100-F72))*G72 -> 0.66206897 | J72: =((100-E72)/(100-F72))*H72 -> 6.6206897 | K72: =B72*(D72/$B$2)*((100-E72)/(100-$C$2)) -> 0 | L72: 0 | M72: =((I72-$D$2)*4+(J72-$E$2)*0.4) -> -0.51944828 | N72: =K72-M72 -> 0.51944828 | O72: 47.245 | P72: =O72-N72 -> 46.725552 | Q72: =O72*0.9777 -> 46.191437 | R72: =Q72-N72 -> 45.671988 | S72: 66.5875 | T72: =(S72*$T$9/$S$9)*0.707 -> 39.231135 | U72: =T72-N72 -> 38.711687 | V72: =(O72*0.5)+(T72*0.5) -> 43.238068 | W72: =V72+$W$9 -> 66.738068 | X72: =V72-N72 -> 42.718619
...

Sheet HBA
F1: HBA
A2: Month | B2: HBA CV 6322 Kcal/Kg GAR, TM = 8%, TS = 0.8% AR, Ash = 15% AR | C2: HBA I CV 5300 Kcal/Kg GAR, TM = 21.32%, TS = 0.75% AR, Ash = 6.04% AR | D2: HBA I Diff. with prev. month | E2: MAX. HBA I | F2: MIN. HBA I | G2: HBA II CV 4100 Kcal/Kg GAR, TM = 35.73%, TS = 0.23% AR, Ash = 3.90% AR | H2: HBA II Diff. with prev. month | I2: MAX. HBA II | J2: MIN. HBA II | K2: HBA III CV 3400 Kcal/Kg GAR, TM = 44.30%, TS = 0.24% AR, Ash = 3.88% AR | L2: HBA III Diff. with prev. month | M2: MAX. HBA III | N2: MIN. HBA III
A3: Jan-15 | B3: 63.84 | E3: =MAX(C3:C14) -> 0 | F3: =MIN(C3:C14) -> 0 | I3: =MAX(G3:G14) -> 0 | J3: =MIN(G3:G14) -> 0 | M3: =MAX(K3:K14) -> 0 | N3: =MIN(K3:K14) -> 0
A4: Feb-15 | B4: 62.92
A5: Mar-15 | B5: 67.76
A6: Apr-15 | B6: 64.48
A7: May-15 | B7: 61.08
A8: Jun-15 | B8: 59.59
A9: Jul-15 | B9: 59.19
A10: Aug-15 | B10: 59.14
A11: Sep-15 | B11: 58.21
A12: Oct-15 | B12: 57.39
A13: Nov-15 | B13: 54.43
A14: Dec-15 | B14: 53.51
A15: Jan-16 | B15: 53.2 | E15: =MAX(C15:C26) -> 0 | F15: =MIN(C15:C26) -> 0 | I15: =MAX(G15:G26) -> 0 | J15: =MIN(G15:G26) -> 0 | M15: =MAX(K15:K26) -> 0 | N15: =MIN(K15:K26) -> 0
A16: Feb-16 | B16: 50.92
A17: Mar-16 | B17: 51.62
A18: Apr-16 | B18: 52.32
A19: May-16 | B19: 51.2
A20: Jun-16 | B20: 51.81
A21: Jul-16 | B21: 53
A22: Aug-16 | B22: 58.37
A23: Sep-16 | B23: 63.93
A24: Oct-16 | B24: 69.07
A25: Nov-16 | B25: 84.89
A26: Dec-16 | B26: 101.69
A27: Jan-17 | B27: 86.23 | E27: =MAX(C27:C38) -> 0 | F27: =MIN(C27:C38) -> 0 | I27: =MAX(G27:G38) -> 0 | J27: =MIN(G27:G38) -> 0 | M27: =MAX(K27:K38) -> 0 | N27: =MIN(K27:K38) -> 0
A28: Feb-17 | B28: 83.32
A29: Mar-17 | B29: 81.9
A30: Apr-17 | B30: 82.51
A31: May-17 | B31: 83.81
A32: Jun-17 | B32: 75.46
A33: Jul-17 | B33: 78.95
A34: Aug-17 | B34: 83.97
A35: Sep-17 | B35: 92.03
A36: Oct-17 | B36: 93.99
A37: Nov-17 | B37: 94.8
A38: Dec-17 | B38: 94.04
A39: Jan-18 | B39: 95.54 | E39: =MAX(C39:C50) -> 0 | F39: =MIN(C39:C50) -> 0 | I39: =MAX(G39:G50) -> 0 | J39: =MIN(G39:G50) -> 0 | M39: =MAX(K39:K50) -> 0 | N39: =MIN(K39:K50) -> 0
A40: Feb-18 | B40: 100.69
...

Sheet BAC
A1: New Formula for coal price from Indonesian Government
A2: The price is minimum price from MINER
A4: HBA Formula (in 1st)
A5: HBA = (0.7*x1) + (0.3*x2) {US$/ton)
A6: X1 | B6: 70% derived from the weighted average FOB vessel sales price from the fourth week two months prior to the first week of the previous month
A7: X2 | B7: 30% from the weighted average FOB vessel sales price during the second and third weeks of two months prior.
A9: HBA Formula (in 15th)
A10: HBA = (0.7*x1) + (0.3*x2) {US$/ton)
A11: X1 | B11: 70% based on the weighted average FOB vessel sales price during the second and third weeks of the previous month.
A12: X2 | B12: 30% from the fourth week two months prior to the first week of the previous month.
A14: Spec | B14: GAR | C14: TM | D14: TS | E14: ASH | F14: Details
A15: HBA 0 | B15: 6322 | C15: 12.26 | D15: 0.66 | E15: 7.94 | F15: > 6000 GAR
A16: HBA I | B16: 5300 | C16: 21.32 | D16: 0.75 | E16: 6.04 | F16: > 5300 GAR - <6000 GAR
A17: HBA II | B17: 4100 | C17: 35.73 | D17: 0.23 | E17: 3.9 | F17: > 4100 GAR - <5,300 GAR
F18: < 4100 GAR - >3400 GAR
A19: HBA III | B19: 3400 | C19: 44.3 | D19: 0.24 | E19: 3.88 | F19: <3400 GAR
A20: HBA 90 | B20: 6322 | C20: 12.26 | D20: 0.66 | E20: 7.94 | F20: Domestic
A22: HBA Price
A23: Month | B23: HBA 0 | C23: HBA I | D23: HBA II | E23: HBA III
A24: 43831 | B24: 65.93
A25: 43862 | B25: 66.89
A26: 43891 | B26: 67.08
A27: 43922 | B27: 65.77
A28: 43952 | B28: 61.11
A29: 43983 | B29: 52.98
A30: 44013 | B30: 52.16
A31: 44044 | B31: 50.34
A32: 44075 | B32: 49.42
A33: 44105 | B33: 51
A34: 44136 | B34: 55.71
A35: 44166 | B35: 59.65
... A61: 44980 | B61: 277.05
A62: 45008 | B62: 283.08 | C62: 136.7 | D62: 102.26
A63: 45039 | B63: 265.25 | C63: 102.53 | D63: 87.81
A64: 45069 | B64: 206.16 | C64: 119.64 | D64: 82.23
A65: 45100 | B65: 191.26 | C65: 112.59 | D65: 78.35
A66: 45130 | B66: 191.6 | C66: 109.27 | D66: 75.2
A67: 45161 | B67: 179.9 | C67: 84.75 | D67: 57.38 | E67: 31.96
A68: 45192 | B68: 133.13 | C68: 89.11 | D68: 53.83 | E68: 31.82
A69: 45222 | B69: 123.96 | C69: 81.38 | D69: 50.41 | E69: 25.5
...
